import type { REPLServer, ReplOptions } from 'repl';
import { Recoverable, start as originalStart } from 'repl';
import isRecoverableError from 'is-recoverable-error';
import { promisify } from 'util';
import { Domain } from 'domain';

// Utility, inverse of Readonly<T>
type Mutable<T> = {
  -readonly[P in keyof T]: T[P]
};

export type OriginalEvalFunction = (input: string, context: any, filename: string) => Promise<any>;
export type AsyncEvalFunction = (originalEval: OriginalEvalFunction, input: string, context: any, filename: string) => Promise<any>;

export type AsyncREPLOptions = Omit<ReplOptions, 'eval'> & {
  start?: typeof originalStart,
  wrapCallbackError?: (err: Error) => Error;
  asyncEval: AsyncEvalFunction;
};

export type EvalStartEvent = {
  input: string;
};
export type EvalFinishEvent = EvalStartEvent & ({
  success: true;
} | {
  success: false;
  err: unknown;
  recoverable: boolean;
});

export const evalStart = Symbol('async-repl:evalStart');
export const evalFinish = Symbol('async-repl:evalFinish');

// Start a REPLSever that supports asynchronous evaluation, rather than just
// synchronous, and integrates nicely with Ctrl+C handling in that respect.
export function start(opts: AsyncREPLOptions): REPLServer {
  const repl = (opts.start ?? originalStart)(opts);
  const { asyncEval, wrapCallbackError = err => err, breakEvalOnSigint } = opts;
  const originalEval = promisify(wrapNoSyncDomainError(repl.eval.bind(repl)));

  (repl as Mutable<typeof repl>).eval = async(
    input: string,
    context: any,
    filename: string,
    callback: (err: Error|null, result?: any) => void): Promise<void> => {
    let result;
    repl.emit(evalStart, { input } as EvalStartEvent);

    try {
      let sigintListener: (() => void) | undefined = undefined;
      let previousSigintListeners: any[] = [];
      try {
        result = await new Promise((resolve, reject) => {
          if (breakEvalOnSigint) {
            // Handle SIGINT (Ctrl+C) that occurs while we are stuck in `await`
            // by racing a listener for 'SIGINT' against the evalResult Promise.
            // We remove all 'SIGINT' listeners and install our own.
            sigintListener = (): void => {
              // Reject with an exception similar to one thrown by Node.js
              // itself if the `customEval` itself is interrupted.
              reject(new Error('Asynchronous execution was interrupted by `SIGINT`'));
            };
            previousSigintListeners = repl.rawListeners('SIGINT');

            repl.removeAllListeners('SIGINT');
            repl.once('SIGINT', sigintListener);
          }

          const evalResult = asyncEval(originalEval, input, context, filename);

          if (sigintListener !== undefined) {
            process.once('SIGINT', sigintListener);
          }
          evalResult.then(resolve, reject);
        });
      } finally {
        // Remove our 'SIGINT' listener and re-install the REPL one(s).
        if (sigintListener !== undefined) {
          repl.removeListener('SIGINT', sigintListener);
          process.removeListener('SIGINT', sigintListener);
        }
        for (const listener of previousSigintListeners) {
          repl.on('SIGINT', listener);
        }
      }
    } catch (err) {
      try {
        if (isRecoverableError(input)) {
          repl.emit(evalFinish, { input, success: false, err, recoverable: true } as EvalFinishEvent);
          return callback(new Recoverable(err));
        }
        repl.emit(evalFinish, { input, success: false, err, recoverable: false } as EvalFinishEvent);
        return callback(err);
      } catch (callbackErr) {
        return callback(wrapCallbackError(callbackErr));
      }
    }
    try {
      repl.emit(evalFinish, { input, success: true } as EvalFinishEvent);
      return callback(null, result);
    } catch (callbackErr) {
      return callback(wrapCallbackError(callbackErr));
    }
  };

  return repl;
}

function wrapNoSyncDomainError<Args extends any[], Ret>(fn: (...args: Args) => Ret) {
  return (...args: Args): Ret => {
    const origEmit = Domain.prototype.emit;

    // When the Node.js core REPL encounters an exception during synchronous
    // evaluation, it does not pass the exception value to the callback
    // (or in this case, reject the Promise here), as one might inspect.
    // Instead, it skips straight ahead to abandoning evaluation and acts
    // as if the error had been thrown asynchronously. This works for them,
    // but for us that's not great, because we rely on the core eval function
    // calling its callback in order to be informed about a possible error
    // that occurred (... and in order for this async function to finish at all.)
    // We monkey-patch `process.domain.emit()` to avoid that, and instead
    // handle a possible error ourselves:
    // https://github.com/nodejs/node/blob/59ca56eddefc78bab87d7e8e074b3af843ab1bc3/lib/repl.js#L488-L493
    // It's not clear why this is done this way in Node.js, however,
    // removing the linked code does lead to failures in the Node.js test
    // suite, so somebody sufficiently motivated could probably find out.
    // For now, this is a hack and probably not considered officially
    // supported, but it works.
    // We *may* want to consider not relying on the built-in eval function
    // at all at some point.
    Domain.prototype.emit = function(ev: string, ...eventArgs: any[]): boolean {
      if (ev === 'error') {
        this.exit();
        throw eventArgs[0];
      }
      return origEmit.call(this, ev, ...eventArgs);
    };

    try {
      return fn(...args);
    } finally {
      // Reset the `emit` function after synchronous evaluation, because
      // we need the Domain functionality for the asynchronous bits.
      Domain.prototype.emit = origEmit;
    }
  };
}

